


2021-10-10-15:18:15    NEW_EXP: Starting Figure generation procedure
2021-10-10-15:18:15    INFO: Calling: __init__...
2021-10-10-15:18:15    ERROR: Traceback (most recent call last):
  File "/home/user/villar/PCDNet/src/lib/logger.py", line 24, in try_call_log
    return func(*args, **kwargs)
  File "04_generate_figures.py", line 40, in __init__
    self.exp_params = load_exp_config_file(exp_path)
  File "/home/user/villar/PCDNet/src/lib/config.py", line 32, in load_exp_config_file
    with open(exp_config,) as file:
FileNotFoundError: [Errno 2] No such file or directory: '/home/user/villar/PCDNet/src/../models/NGSIM/experiment_params.json'




2021-10-10-15:19:12    NEW_EXP: Starting Figure generation procedure
2021-10-10-15:19:12    INFO: Calling: __init__...
2021-10-10-15:19:12    ERROR: Traceback (most recent call last):
  File "/home/user/villar/PCDNet/src/lib/logger.py", line 24, in try_call_log
    return func(*args, **kwargs)
  File "04_generate_figures.py", line 40, in __init__
    self.exp_params = load_exp_config_file(exp_path)
  File "/home/user/villar/PCDNet/src/lib/config.py", line 33, in load_exp_config_file
    exp_params = json.load(file)
  File "/home/user/villar/anaconda3/lib/python3.8/json/__init__.py", line 293, in load
    return loads(fp.read(),
  File "/home/user/villar/anaconda3/lib/python3.8/json/__init__.py", line 357, in loads
    return _default_decoder.decode(s)
  File "/home/user/villar/anaconda3/lib/python3.8/json/decoder.py", line 337, in decode
    obj, end = self.raw_decode(s, idx=_w(s, 0).end())
  File "/home/user/villar/anaconda3/lib/python3.8/json/decoder.py", line 353, in raw_decode
    obj, end = self.scan_once(s, idx)
json.decoder.JSONDecodeError: Expecting property name enclosed in double quotes: line 38 column 20 (char 831)




2021-10-10-15:19:23    NEW_EXP: Starting Figure generation procedure
2021-10-10-15:19:23    INFO: Calling: __init__...
2021-10-10-15:19:23    INFO: Calling: create_directory...
2021-10-10-15:19:23    INFO: Calling: load_data...
2021-10-10-15:19:23    INFO: Calling: setup_model...
2021-10-10-15:19:23    INFO: Calling: setup_model...
2021-10-10-15:19:23    INFO: Calling: load_checkpoint...
2021-10-10-15:19:23    ERROR: Traceback (most recent call last):
  File "/home/user/villar/PCDNet/src/lib/logger.py", line 24, in try_call_log
    return func(*args, **kwargs)
  File "/home/user/villar/PCDNet/src/lib/setup_model.py", line 117, in load_checkpoint
    checkpoint = torch.load(checkpoint_path)
  File "/home/user/villar/anaconda3/lib/python3.8/site-packages/torch/serialization.py", line 592, in load
    return _load(opened_zipfile, map_location, pickle_module, **pickle_load_args)
  File "/home/user/villar/anaconda3/lib/python3.8/site-packages/torch/serialization.py", line 851, in _load
    result = unpickler.load()
  File "/home/user/villar/anaconda3/lib/python3.8/site-packages/torch/serialization.py", line 843, in persistent_load
    load_tensor(data_type, size, key, _maybe_decode_ascii(location))
  File "/home/user/villar/anaconda3/lib/python3.8/site-packages/torch/serialization.py", line 832, in load_tensor
    loaded_storages[key] = restore_location(storage, location)
  File "/home/user/villar/anaconda3/lib/python3.8/site-packages/torch/serialization.py", line 175, in default_restore_location
    result = fn(storage, location)
  File "/home/user/villar/anaconda3/lib/python3.8/site-packages/torch/serialization.py", line 151, in _cuda_deserialize
    device = validate_cuda_device(location)
  File "/home/user/villar/anaconda3/lib/python3.8/site-packages/torch/serialization.py", line 135, in validate_cuda_device
    raise RuntimeError('Attempting to deserialize object on a CUDA '
RuntimeError: Attempting to deserialize object on a CUDA device but torch.cuda.is_available() is False. If you are running on a CPU-only machine, please use torch.load with map_location=torch.device('cpu') to map your storages to the CPU.




2021-10-10-15:19:31    NEW_EXP: Starting Figure generation procedure
2021-10-10-15:19:31    INFO: Calling: __init__...
2021-10-10-15:19:31    INFO: Calling: create_directory...
2021-10-10-15:19:31    INFO: Calling: load_data...
2021-10-10-15:19:31    INFO: Calling: setup_model...
2021-10-10-15:19:31    INFO: Calling: setup_model...
2021-10-10-15:19:31    INFO: Calling: load_checkpoint...
2021-10-10-15:19:32    INFO: Calling: generate_figs...
2021-10-10-15:19:34    INFO: Calling: create_directory...
2021-10-10-15:19:35    ERROR: Traceback (most recent call last):
  File "/home/user/villar/PCDNet/src/lib/logger.py", line 24, in try_call_log
    return func(*args, **kwargs)
  File "/home/user/villar/anaconda3/lib/python3.8/site-packages/torch/autograd/grad_mode.py", line 27, in decorate_context
    return func(*args, **kwargs)
  File "04_generate_figures.py", line 147, in generate_figs
    color = colors.to_rgb(COLORS[(object_ids[0, i]-1)//3])
IndexError: list index out of range




2021-10-10-15:23:15    NEW_EXP: Starting Figure generation procedure
2021-10-10-15:23:15    INFO: Calling: __init__...
2021-10-10-15:23:15    INFO: Calling: create_directory...
2021-10-10-15:23:15    INFO: Calling: load_data...
2021-10-10-15:23:15    INFO: Calling: setup_model...
2021-10-10-15:23:15    INFO: Calling: setup_model...
2021-10-10-15:23:15    INFO: Calling: load_checkpoint...
2021-10-10-15:23:17    INFO: Calling: generate_figs...
2021-10-10-15:23:17    ERROR: Traceback (most recent call last):
  File "/home/user/villar/PCDNet/src/lib/logger.py", line 24, in try_call_log
    return func(*args, **kwargs)
  File "/home/user/villar/anaconda3/lib/python3.8/site-packages/torch/autograd/grad_mode.py", line 27, in decorate_context
    return func(*args, **kwargs)
  File "04_generate_figures.py", line 82, in generate_figs
    dif = len(self.model.prototypes) - len(COLORS)
UnboundLocalError: local variable 'COLORS' referenced before assignment




2021-10-10-15:23:35    NEW_EXP: Starting Figure generation procedure
2021-10-10-15:23:35    INFO: Calling: __init__...
2021-10-10-15:23:35    INFO: Calling: create_directory...
2021-10-10-15:23:35    INFO: Calling: load_data...
2021-10-10-15:23:35    INFO: Calling: setup_model...
2021-10-10-15:23:35    INFO: Calling: setup_model...
2021-10-10-15:23:35    INFO: Calling: load_checkpoint...
2021-10-10-15:23:36    INFO: Calling: generate_figs...
2021-10-10-15:23:36    ERROR: Traceback (most recent call last):
  File "/home/user/villar/PCDNet/src/lib/logger.py", line 24, in try_call_log
    return func(*args, **kwargs)
  File "/home/user/villar/anaconda3/lib/python3.8/site-packages/torch/autograd/grad_mode.py", line 27, in decorate_context
    return func(*args, **kwargs)
  File "04_generate_figures.py", line 81, in generate_figs
    print(COLORS)
UnboundLocalError: local variable 'COLORS' referenced before assignment




2021-10-10-15:23:56    NEW_EXP: Starting Figure generation procedure
2021-10-10-15:23:56    INFO: Calling: __init__...
2021-10-10-15:23:56    INFO: Calling: create_directory...
2021-10-10-15:23:56    INFO: Calling: load_data...
2021-10-10-15:23:56    INFO: Calling: setup_model...
2021-10-10-15:23:56    INFO: Calling: setup_model...
2021-10-10-15:23:56    INFO: Calling: load_checkpoint...
2021-10-10-15:23:58    INFO: Calling: generate_figs...
2021-10-10-15:23:59    INFO: Calling: create_directory...
2021-10-10-15:24:00    ERROR: Traceback (most recent call last):
  File "/home/user/villar/PCDNet/src/lib/logger.py", line 24, in try_call_log
    return func(*args, **kwargs)
  File "/home/user/villar/anaconda3/lib/python3.8/site-packages/torch/autograd/grad_mode.py", line 27, in decorate_context
    return func(*args, **kwargs)
  File "04_generate_figures.py", line 153, in generate_figs
    color = colors.to_rgb(COLORS[(object_ids[0, i]-1)//3])
IndexError: list index out of range




2021-10-10-15:27:56    NEW_EXP: Starting Figure generation procedure
2021-10-10-15:27:56    INFO: Calling: __init__...
2021-10-10-15:27:56    INFO: Calling: create_directory...
2021-10-10-15:27:56    INFO: Calling: load_data...
2021-10-10-15:27:56    INFO: Calling: setup_model...
2021-10-10-15:27:56    INFO: Calling: setup_model...
2021-10-10-15:27:56    INFO: Calling: load_checkpoint...
2021-10-10-15:27:57    INFO: Calling: generate_figs...
2021-10-10-15:27:59    INFO: Calling: create_directory...
2021-10-10-15:28:00    ERROR: Traceback (most recent call last):
  File "/home/user/villar/PCDNet/src/lib/logger.py", line 24, in try_call_log
    return func(*args, **kwargs)
  File "/home/user/villar/anaconda3/lib/python3.8/site-packages/torch/autograd/grad_mode.py", line 27, in decorate_context
    return func(*args, **kwargs)
  File "04_generate_figures.py", line 161, in generate_figs
    img = self.model.compose_templates(
  File "/home/user/villar/PCDNet/src/models/PrototypicalDissentangler.py", line 208, in compose_templates
    cur_recons = cur_obj * cur_mask + cur_recons * (1 - cur_mask)
RuntimeError: The size of tensor a (35) must match the size of tensor b (194) at non-singleton dimension 3




2021-10-10-15:31:01    NEW_EXP: Starting Figure generation procedure
2021-10-10-15:31:01    INFO: Calling: __init__...
2021-10-10-15:31:01    INFO: Calling: create_directory...
2021-10-10-15:31:01    INFO: Calling: load_data...
2021-10-10-15:31:01    INFO: Calling: setup_model...
2021-10-10-15:31:01    INFO: Calling: setup_model...
2021-10-10-15:31:01    INFO: Calling: load_checkpoint...
2021-10-10-15:31:02    INFO: Calling: generate_figs...
2021-10-10-15:31:04    INFO: Calling: create_directory...
2021-10-10-15:31:05    ERROR: Traceback (most recent call last):
  File "/home/user/villar/PCDNet/src/lib/logger.py", line 24, in try_call_log
    return func(*args, **kwargs)
  File "/home/user/villar/anaconda3/lib/python3.8/site-packages/torch/autograd/grad_mode.py", line 27, in decorate_context
    return func(*args, **kwargs)
  File "04_generate_figures.py", line 177, in generate_figs
    color = colors.to_rgb(COLORS[i])
IndexError: list index out of range




2021-10-10-15:31:45    NEW_EXP: Starting Figure generation procedure
2021-10-10-15:31:45    INFO: Calling: __init__...
2021-10-10-15:31:45    INFO: Calling: create_directory...
2021-10-10-15:31:45    INFO: Calling: load_data...
2021-10-10-15:31:45    INFO: Calling: setup_model...
2021-10-10-15:31:45    INFO: Calling: setup_model...
2021-10-10-15:31:45    INFO: Calling: load_checkpoint...
2021-10-10-15:31:47    INFO: Calling: generate_figs...
2021-10-10-15:31:47    ERROR: Traceback (most recent call last):
  File "/home/user/villar/PCDNet/src/lib/logger.py", line 24, in try_call_log
    return func(*args, **kwargs)
  File "/home/user/villar/anaconda3/lib/python3.8/site-packages/torch/autograd/grad_mode.py", line 27, in decorate_context
    return func(*args, **kwargs)
  File "04_generate_figures.py", line 83, in generate_figs
    dif = len(self.model.num_objects) - len(COLORS)
TypeError: object of type 'int' has no len()




2021-10-10-15:31:55    NEW_EXP: Starting Figure generation procedure
2021-10-10-15:31:55    INFO: Calling: __init__...
2021-10-10-15:31:55    INFO: Calling: create_directory...
2021-10-10-15:31:55    INFO: Calling: load_data...
2021-10-10-15:31:55    INFO: Calling: setup_model...
2021-10-10-15:31:55    INFO: Calling: setup_model...
2021-10-10-15:31:55    INFO: Calling: load_checkpoint...
2021-10-10-15:31:57    INFO: Calling: generate_figs...
2021-10-10-15:31:58    INFO: Calling: create_directory...
2021-10-10-15:31:59    INFO: Calling: generate_figs...
2021-10-10-15:32:00    INFO: Calling: create_directory...
2021-10-10-15:32:01    INFO: Calling: generate_figs...
2021-10-10-15:32:02    INFO: Calling: create_directory...
2021-10-10-15:32:03    INFO: Calling: generate_figs...
2021-10-10-15:32:04    INFO: Calling: create_directory...
2021-10-10-15:32:05    INFO: Calling: generate_figs...
2021-10-10-15:32:06    INFO: Calling: create_directory...
2021-10-10-15:32:07    INFO: Calling: generate_global_figs...



2021-10-10-15:36:51    NEW_EXP: Starting Figure generation procedure
2021-10-10-15:36:51    INFO: Calling: __init__...
2021-10-10-15:36:51    INFO: Calling: create_directory...
2021-10-10-15:36:51    INFO: Calling: load_data...
2021-10-10-15:36:51    INFO: Calling: setup_model...
2021-10-10-15:36:51    INFO: Calling: setup_model...
2021-10-10-15:36:51    INFO: Calling: load_checkpoint...
2021-10-10-15:36:52    INFO: Calling: generate_figs...
2021-10-10-15:36:54    INFO: Calling: create_directory...
2021-10-10-15:36:55    INFO: Calling: generate_figs...
2021-10-10-15:36:55    INFO: Calling: create_directory...
2021-10-10-15:36:57    INFO: Calling: generate_figs...
2021-10-10-15:36:57    INFO: Calling: create_directory...
2021-10-10-15:36:58    INFO: Calling: generate_figs...
2021-10-10-15:36:59    INFO: Calling: create_directory...
2021-10-10-15:37:00    INFO: Calling: generate_figs...
2021-10-10-15:37:01    INFO: Calling: create_directory...
2021-10-10-15:37:02    INFO: Calling: generate_global_figs...



2021-10-10-15:37:58    NEW_EXP: Starting Figure generation procedure
2021-10-10-15:37:58    INFO: Calling: __init__...
2021-10-10-15:37:58    INFO: Calling: create_directory...
2021-10-10-15:37:58    INFO: Calling: load_data...
2021-10-10-15:37:58    INFO: Calling: setup_model...
2021-10-10-15:37:58    INFO: Calling: setup_model...
2021-10-10-15:37:58    INFO: Calling: load_checkpoint...
2021-10-10-15:37:59    INFO: Calling: generate_figs...
2021-10-10-15:38:01    INFO: Calling: create_directory...
2021-10-10-15:38:02    INFO: Calling: generate_figs...
2021-10-10-15:38:03    INFO: Calling: create_directory...
2021-10-10-15:38:04    INFO: Calling: generate_figs...
2021-10-10-15:38:04    INFO: Calling: create_directory...
2021-10-10-15:38:06    INFO: Calling: generate_figs...
2021-10-10-15:38:06    INFO: Calling: create_directory...
2021-10-10-15:38:07    INFO: Calling: generate_figs...
2021-10-10-15:38:08    INFO: Calling: create_directory...
2021-10-10-15:38:09    INFO: Calling: generate_global_figs...



2021-10-10-16:56:56    NEW_EXP: Starting Figure generation procedure
2021-10-10-16:56:56    INFO: Calling: __init__...
2021-10-10-16:56:56    INFO: Calling: create_directory...
2021-10-10-16:56:56    INFO: Calling: load_data...
2021-10-10-16:56:56    INFO: Calling: setup_model...
2021-10-10-16:56:56    INFO: Calling: setup_model...
2021-10-10-16:56:56    INFO: Calling: load_checkpoint...
2021-10-10-16:56:58    INFO: Calling: generate_figs...
2021-10-10-16:56:59    INFO: Calling: create_directory...
2021-10-10-16:57:00    ERROR: Traceback (most recent call last):
  File "/home/user/villar/PCDNet/src/lib/logger.py", line 24, in try_call_log
    return func(*args, **kwargs)
  File "/home/user/villar/anaconda3/lib/python3.8/site-packages/torch/autograd/grad_mode.py", line 27, in decorate_context
    return func(*args, **kwargs)
  File "04_generate_figures.py", line 169, in generate_figs
    img = self.model.compose_templates(
  File "/home/user/villar/PCDNet/src/models/PrototypicalDissentangler.py", line 208, in compose_templates
    cur_recons = cur_obj * cur_mask + cur_recons * (1 - cur_mask)
RuntimeError: The size of tensor a (9) must match the size of tensor b (3) at non-singleton dimension 1




2021-10-10-17:01:57    NEW_EXP: Starting Figure generation procedure
2021-10-10-17:01:57    INFO: Calling: __init__...
2021-10-10-17:01:57    INFO: Calling: create_directory...
2021-10-10-17:01:57    INFO: Calling: load_data...
2021-10-10-17:01:57    INFO: Calling: setup_model...
2021-10-10-17:01:57    INFO: Calling: setup_model...
2021-10-10-17:01:57    INFO: Calling: load_checkpoint...
2021-10-10-17:01:58    INFO: Calling: generate_figs...
2021-10-10-17:01:59    INFO: Calling: create_directory...
2021-10-10-17:02:00    INFO: Calling: generate_figs...
2021-10-10-17:02:01    INFO: Calling: create_directory...
2021-10-10-17:02:02    INFO: Calling: generate_figs...
2021-10-10-17:02:02    INFO: Calling: create_directory...
2021-10-10-17:02:03    INFO: Calling: generate_figs...
2021-10-10-17:02:03    INFO: Calling: create_directory...
2021-10-10-17:02:05    INFO: Calling: generate_figs...
2021-10-10-17:02:05    INFO: Calling: create_directory...
2021-10-10-17:02:06    INFO: Calling: generate_global_figs...
