


2021-10-09-14:13:30    NEW_EXP: Starting DecompNet evaluation procedure
2021-10-09-14:13:30    INFO: Calling: __init__...
2021-10-09-14:13:30    ERROR: Traceback (most recent call last):
  File "/home/user/villar/PCDNet/src/lib/logger.py", line 24, in try_call_log
    return func(*args, **kwargs)
  File "03_evaluate_segmentation.py", line 34, in __init__
    self.exp_params = load_exp_config_file(exp_path)
  File "/home/user/villar/PCDNet/src/lib/config.py", line 33, in load_exp_config_file
    exp_params = json.load(file)
  File "/home/user/villar/anaconda3/lib/python3.8/json/__init__.py", line 293, in load
    return loads(fp.read(),
  File "/home/user/villar/anaconda3/lib/python3.8/json/__init__.py", line 357, in loads
    return _default_decoder.decode(s)
  File "/home/user/villar/anaconda3/lib/python3.8/json/decoder.py", line 337, in decode
    obj, end = self.raw_decode(s, idx=_w(s, 0).end())
  File "/home/user/villar/anaconda3/lib/python3.8/json/decoder.py", line 353, in raw_decode
    obj, end = self.scan_once(s, idx)
json.decoder.JSONDecodeError: Expecting ',' delimiter: line 45 column 1 (char 943)




2021-10-09-14:14:05    NEW_EXP: Starting DecompNet evaluation procedure
2021-10-09-14:14:05    INFO: Calling: __init__...
2021-10-09-14:14:05    ERROR: Traceback (most recent call last):
  File "/home/user/villar/PCDNet/src/lib/logger.py", line 24, in try_call_log
    return func(*args, **kwargs)
  File "03_evaluate_segmentation.py", line 34, in __init__
    self.exp_params = load_exp_config_file(exp_path)
  File "/home/user/villar/PCDNet/src/lib/config.py", line 33, in load_exp_config_file
    exp_params = json.load(file)
  File "/home/user/villar/anaconda3/lib/python3.8/json/__init__.py", line 293, in load
    return loads(fp.read(),
  File "/home/user/villar/anaconda3/lib/python3.8/json/__init__.py", line 357, in loads
    return _default_decoder.decode(s)
  File "/home/user/villar/anaconda3/lib/python3.8/json/decoder.py", line 337, in decode
    obj, end = self.raw_decode(s, idx=_w(s, 0).end())
  File "/home/user/villar/anaconda3/lib/python3.8/json/decoder.py", line 353, in raw_decode
    obj, end = self.scan_once(s, idx)
json.decoder.JSONDecodeError: Expecting ',' delimiter: line 25 column 3 (char 551)




2021-10-09-14:14:20    NEW_EXP: Starting DecompNet evaluation procedure
2021-10-09-14:14:20    INFO: Calling: __init__...
2021-10-09-14:14:20    INFO: Calling: create_directory...
2021-10-09-14:14:20    INFO: Calling: load_data...
2021-10-09-14:14:20    ERROR: Traceback (most recent call last):
  File "/home/user/villar/PCDNet/src/lib/logger.py", line 24, in try_call_log
    return func(*args, **kwargs)
  File "03_evaluate_segmentation.py", line 52, in load_data
    self.test_set = data.load_data(exp_params=self.exp_params, split="test")
  File "/home/user/villar/PCDNet/src/data/load_data.py", line 37, in load_data
    dataset = Tetrominoes(
  File "/home/user/villar/PCDNet/src/data/tetrominoes.py", line 30, in __init__
    assert os.path.exists(data_path)
AssertionError




2021-10-09-14:16:44    NEW_EXP: Starting DecompNet evaluation procedure
2021-10-09-14:16:44    INFO: Calling: __init__...
2021-10-09-14:16:44    INFO: Calling: create_directory...
2021-10-09-14:16:44    INFO: Calling: load_data...
2021-10-09-14:16:44    ERROR: Traceback (most recent call last):
  File "/home/user/villar/PCDNet/src/lib/logger.py", line 24, in try_call_log
    return func(*args, **kwargs)
  File "03_evaluate_segmentation.py", line 52, in load_data
    self.test_set = data.load_data(exp_params=self.exp_params, split="test")
  File "/home/user/villar/PCDNet/src/data/load_data.py", line 37, in load_data
    dataset = Tetrominoes(
  File "/home/user/villar/PCDNet/src/data/tetrominoes.py", line 30, in __init__
    assert os.path.exists(data_path)
AssertionError




2021-10-09-14:16:59    NEW_EXP: Starting DecompNet evaluation procedure
2021-10-09-14:16:59    INFO: Calling: __init__...
2021-10-09-14:16:59    INFO: Calling: create_directory...
2021-10-09-14:16:59    INFO: Calling: load_data...
2021-10-09-14:16:59    ERROR: Traceback (most recent call last):
  File "/home/user/villar/PCDNet/src/lib/logger.py", line 24, in try_call_log
    return func(*args, **kwargs)
  File "03_evaluate_segmentation.py", line 52, in load_data
    self.test_set = data.load_data(exp_params=self.exp_params, split="test")
  File "/home/user/villar/PCDNet/src/data/load_data.py", line 38, in load_data
    dataset = Tetrominoes(
  File "/home/user/villar/PCDNet/src/data/tetrominoes.py", line 30, in __init__
    assert os.path.exists(data_path)
AssertionError




2021-10-09-14:18:22    NEW_EXP: Starting DecompNet evaluation procedure
2021-10-09-14:18:22    INFO: Calling: __init__...
2021-10-09-14:18:22    INFO: Calling: create_directory...
2021-10-09-14:18:22    INFO: Calling: load_data...
2021-10-09-14:18:22    ERROR: Traceback (most recent call last):
  File "/home/user/villar/PCDNet/src/lib/logger.py", line 24, in try_call_log
    return func(*args, **kwargs)
  File "03_evaluate_segmentation.py", line 52, in load_data
    self.test_set = data.load_data(exp_params=self.exp_params, split="test")
  File "/home/user/villar/PCDNet/src/data/load_data.py", line 38, in load_data
    dataset = Tetrominoes(
  File "/home/user/villar/PCDNet/src/data/tetrominoes.py", line 31, in __init__
    assert os.path.exists(data_path)
AssertionError




2021-10-09-14:18:56    NEW_EXP: Starting DecompNet evaluation procedure
2021-10-09-14:18:56    INFO: Calling: __init__...
2021-10-09-14:18:56    INFO: Calling: create_directory...
2021-10-09-14:18:56    INFO: Calling: load_data...
2021-10-09-14:18:56    ERROR: Traceback (most recent call last):
  File "/home/user/villar/PCDNet/src/lib/logger.py", line 24, in try_call_log
    return func(*args, **kwargs)
  File "03_evaluate_segmentation.py", line 52, in load_data
    self.test_set = data.load_data(exp_params=self.exp_params, split="test")
  File "/home/user/villar/PCDNet/src/data/load_data.py", line 38, in load_data
    dataset = Tetrominoes(
  File "/home/user/villar/PCDNet/src/data/tetrominoes.py", line 31, in __init__
    assert os.path.exists(data_path)
AssertionError




2021-10-09-14:19:44    NEW_EXP: Starting DecompNet evaluation procedure
2021-10-09-14:19:44    INFO: Calling: __init__...
2021-10-09-14:19:44    INFO: Calling: create_directory...
2021-10-09-14:19:44    INFO: Calling: load_data...
2021-10-09-14:19:44    ERROR: Traceback (most recent call last):
  File "/home/user/villar/PCDNet/src/lib/logger.py", line 24, in try_call_log
    return func(*args, **kwargs)
  File "03_evaluate_segmentation.py", line 52, in load_data
    self.test_set = data.load_data(exp_params=self.exp_params, split="test")
  File "/home/user/villar/PCDNet/src/data/load_data.py", line 38, in load_data
    dataset = Tetrominoes(
  File "/home/user/villar/PCDNet/src/data/tetrominoes.py", line 31, in __init__
    assert os.path.exists(data_path)
AssertionError




2021-10-09-14:20:41    NEW_EXP: Starting DecompNet evaluation procedure
2021-10-09-14:20:41    INFO: Calling: __init__...
2021-10-09-14:20:41    INFO: Calling: create_directory...
2021-10-09-14:20:41    INFO: Calling: load_data...
2021-10-09-14:20:41    ERROR: Traceback (most recent call last):
  File "/home/user/villar/PCDNet/src/lib/logger.py", line 24, in try_call_log
    return func(*args, **kwargs)
  File "03_evaluate_segmentation.py", line 52, in load_data
    self.test_set = data.load_data(exp_params=self.exp_params, split="test")
  File "/home/user/villar/PCDNet/src/data/load_data.py", line 40, in load_data
    dataset = Tetrominoes(
  File "/home/user/villar/PCDNet/src/data/tetrominoes.py", line 31, in __init__
    assert os.path.exists(data_path)
AssertionError




2021-10-09-14:21:06    NEW_EXP: Starting DecompNet evaluation procedure
2021-10-09-14:21:06    INFO: Calling: __init__...
2021-10-09-14:21:06    INFO: Calling: create_directory...
2021-10-09-14:21:06    INFO: Calling: load_data...
2021-10-09-14:21:06    ERROR: Traceback (most recent call last):
  File "/home/user/villar/PCDNet/src/lib/logger.py", line 24, in try_call_log
    return func(*args, **kwargs)
  File "03_evaluate_segmentation.py", line 52, in load_data
    self.test_set = data.load_data(exp_params=self.exp_params, split="test")
  File "/home/user/villar/PCDNet/src/data/load_data.py", line 38, in load_data
    dataset = Tetrominoes(
  File "/home/user/villar/PCDNet/src/data/tetrominoes.py", line 31, in __init__
    assert os.path.exists(data_path)
AssertionError




2021-10-09-14:21:08    NEW_EXP: Starting DecompNet evaluation procedure
2021-10-09-14:21:08    INFO: Calling: __init__...
2021-10-09-14:21:08    INFO: Calling: create_directory...
2021-10-09-14:21:08    INFO: Calling: load_data...
2021-10-09-14:21:08    ERROR: Traceback (most recent call last):
  File "/home/user/villar/PCDNet/src/lib/logger.py", line 24, in try_call_log
    return func(*args, **kwargs)
  File "03_evaluate_segmentation.py", line 52, in load_data
    self.test_set = data.load_data(exp_params=self.exp_params, split="test")
  File "/home/user/villar/PCDNet/src/data/load_data.py", line 38, in load_data
    dataset = Tetrominoes(
  File "/home/user/villar/PCDNet/src/data/tetrominoes.py", line 31, in __init__
    assert os.path.exists(data_path)
AssertionError




2021-10-09-14:21:24    NEW_EXP: Starting DecompNet evaluation procedure
2021-10-09-14:21:24    INFO: Calling: __init__...
2021-10-09-14:21:24    INFO: Calling: create_directory...
2021-10-09-14:21:24    INFO: Calling: load_data...
2021-10-09-14:21:24    ERROR: Traceback (most recent call last):
  File "/home/user/villar/PCDNet/src/lib/logger.py", line 24, in try_call_log
    return func(*args, **kwargs)
  File "03_evaluate_segmentation.py", line 52, in load_data
    self.test_set = data.load_data(exp_params=self.exp_params, split="test")
  File "/home/user/villar/PCDNet/src/data/load_data.py", line 38, in load_data
    dataset = Tetrominoes(
  File "/home/user/villar/PCDNet/src/data/tetrominoes.py", line 31, in __init__
    assert os.path.exists(data_path)
AssertionError




2021-10-09-14:22:04    NEW_EXP: Starting DecompNet evaluation procedure
2021-10-09-14:22:04    INFO: Calling: __init__...
2021-10-09-14:22:04    INFO: Calling: create_directory...
2021-10-09-14:22:04    INFO: Calling: load_data...
2021-10-09-14:22:04    INFO: Calling: setup_model...
2021-10-09-14:22:04    INFO: Calling: setup_model...
2021-10-09-14:22:04    ERROR: Traceback (most recent call last):
  File "/home/user/villar/PCDNet/src/lib/logger.py", line 24, in try_call_log
    return func(*args, **kwargs)
  File "/home/user/villar/PCDNet/src/lib/setup_model.py", line 22, in setup_model
    pc_params = model_params["PC-Cell"]
KeyError: 'PC-Cell'




2021-10-09-14:22:49    NEW_EXP: Starting DecompNet evaluation procedure
2021-10-09-14:22:49    INFO: Calling: __init__...
2021-10-09-14:22:49    INFO: Calling: create_directory...
2021-10-09-14:22:49    INFO: Calling: load_data...
2021-10-09-14:22:49    INFO: Calling: setup_model...
2021-10-09-14:22:49    INFO: Calling: setup_model...
2021-10-09-14:22:49    INFO: Calling: load_checkpoint...
2021-10-09-14:22:51    INFO: Calling: predict...



2021-10-09-14:37:48    NEW_EXP: Starting Figure generation procedure
2021-10-09-14:37:48    INFO: Calling: __init__...
2021-10-09-14:37:48    INFO: Calling: create_directory...
2021-10-09-14:37:48    INFO: Calling: load_data...
2021-10-09-14:37:48    INFO: Calling: setup_model...
2021-10-09-14:37:48    INFO: Calling: setup_model...
2021-10-09-14:37:48    INFO: Calling: load_checkpoint...
2021-10-09-14:37:50    INFO: Calling: generate_figs...
2021-10-09-14:37:50    ERROR: Traceback (most recent call last):
  File "/home/user/villar/PCDNet/src/lib/logger.py", line 24, in try_call_log
    return func(*args, **kwargs)
  File "/home/user/villar/anaconda3/lib/python3.8/site-packages/torch/autograd/grad_mode.py", line 27, in decorate_context
    return func(*args, **kwargs)
  File "04_generate_figures.py", line 86, in generate_figs
    reconstruction, (objects, object_ids, protos) = self.model(imgs)
  File "/home/user/villar/anaconda3/lib/python3.8/site-packages/torch/nn/modules/module.py", line 889, in _call_impl
    result = self.forward(*input, **kwargs)
  File "/home/user/villar/PCDNet/src/models/PrototypicalDissentangler.py", line 286, in forward
    templates, peaks = self.pc_cell(x, protos)
  File "/home/user/villar/anaconda3/lib/python3.8/site-packages/torch/nn/modules/module.py", line 889, in _call_impl
    result = self.forward(*input, **kwargs)
  File "/home/user/villar/PCDNet/src/models/PhaseCorrelationCell.py", line 97, in forward
    peaks = self.peak_picking(
  File "/home/user/villar/PCDNet/src/models/PhaseCorrelationCell.py", line 150, in peak_picking
    idx = idx % n_cols**2 if not self.grayscale else idx
TypeError: unsupported operand type(s) for %: 'tuple' and 'int'




2021-10-09-14:39:14    NEW_EXP: Starting Figure generation procedure
2021-10-09-14:39:14    INFO: Calling: __init__...
2021-10-09-14:39:14    INFO: Calling: create_directory...
2021-10-09-14:39:14    INFO: Calling: load_data...
2021-10-09-14:39:14    INFO: Calling: setup_model...
2021-10-09-14:39:14    INFO: Calling: setup_model...
2021-10-09-14:39:14    INFO: Calling: load_checkpoint...
2021-10-09-14:39:16    INFO: Calling: generate_figs...
2021-10-09-14:39:16    INFO: Calling: create_directory...
2021-10-09-14:39:17    ERROR: Traceback (most recent call last):
  File "/home/user/villar/PCDNet/src/lib/logger.py", line 24, in try_call_log
    return func(*args, **kwargs)
  File "/home/user/villar/anaconda3/lib/python3.8/site-packages/torch/autograd/grad_mode.py", line 27, in decorate_context
    return func(*args, **kwargs)
  File "04_generate_figures.py", line 133, in generate_figs
    plt.imshow(bin_mask[0, i].detach().cpu(), vmin=0, vmax=1, cmap="gray")
  File "/home/user/villar/anaconda3/lib/python3.8/site-packages/matplotlib/pyplot.py", line 2724, in imshow
    __ret = gca().imshow(
  File "/home/user/villar/anaconda3/lib/python3.8/site-packages/matplotlib/__init__.py", line 1447, in inner
    return func(ax, *map(sanitize_sequence, args), **kwargs)
  File "/home/user/villar/anaconda3/lib/python3.8/site-packages/matplotlib/axes/_axes.py", line 5523, in imshow
    im.set_data(X)
  File "/home/user/villar/anaconda3/lib/python3.8/site-packages/matplotlib/image.py", line 711, in set_data
    raise TypeError("Invalid shape {} for image data"
TypeError: Invalid shape (1, 35, 35) for image data




2021-10-09-14:40:21    NEW_EXP: Starting Figure generation procedure
2021-10-09-14:40:21    INFO: Calling: __init__...
2021-10-09-14:40:21    INFO: Calling: create_directory...
2021-10-09-14:40:21    INFO: Calling: load_data...
2021-10-09-14:40:21    INFO: Calling: setup_model...
2021-10-09-14:40:21    INFO: Calling: setup_model...
2021-10-09-14:40:21    INFO: Calling: load_checkpoint...
2021-10-09-14:40:22    INFO: Calling: generate_figs...
2021-10-09-14:40:23    INFO: Calling: create_directory...
2021-10-09-14:40:23    ERROR: Traceback (most recent call last):
  File "/home/user/villar/PCDNet/src/lib/logger.py", line 24, in try_call_log
    return func(*args, **kwargs)
  File "/home/user/villar/anaconda3/lib/python3.8/site-packages/torch/autograd/grad_mode.py", line 27, in decorate_context
    return func(*args, **kwargs)
  File "04_generate_figures.py", line 151, in generate_figs
    img = protolib.compose_templates(
TypeError: compose_templates() missing 1 required positional argument: 'masks'




2021-10-09-14:41:35    NEW_EXP: Starting Figure generation procedure
2021-10-09-14:41:35    INFO: Calling: __init__...
2021-10-09-14:41:35    INFO: Calling: create_directory...
2021-10-09-14:41:35    INFO: Calling: load_data...
2021-10-09-14:41:35    INFO: Calling: setup_model...
2021-10-09-14:41:35    INFO: Calling: setup_model...
2021-10-09-14:41:35    INFO: Calling: load_checkpoint...
2021-10-09-14:41:37    INFO: Calling: generate_figs...
2021-10-09-14:41:37    INFO: Calling: create_directory...
2021-10-09-14:41:37    ERROR: Traceback (most recent call last):
  File "/home/user/villar/PCDNet/src/lib/logger.py", line 24, in try_call_log
    return func(*args, **kwargs)
  File "/home/user/villar/anaconda3/lib/python3.8/site-packages/torch/autograd/grad_mode.py", line 27, in decorate_context
    return func(*args, **kwargs)
  File "04_generate_figures.py", line 151, in generate_figs
    img = protolib.compose_templates(
TypeError: compose_templates() missing 1 required positional argument: 'masks'




2021-10-09-14:41:51    NEW_EXP: Starting Figure generation procedure
2021-10-09-14:41:51    INFO: Calling: __init__...
2021-10-09-14:41:51    INFO: Calling: create_directory...
2021-10-09-14:41:51    INFO: Calling: load_data...
2021-10-09-14:41:51    INFO: Calling: setup_model...
2021-10-09-14:41:51    INFO: Calling: setup_model...
2021-10-09-14:41:51    INFO: Calling: load_checkpoint...
2021-10-09-14:41:52    INFO: Calling: generate_figs...
2021-10-09-14:41:53    INFO: Calling: create_directory...
2021-10-09-14:41:53    ERROR: Traceback (most recent call last):
  File "/home/user/villar/PCDNet/src/lib/logger.py", line 24, in try_call_log
    return func(*args, **kwargs)
  File "/home/user/villar/anaconda3/lib/python3.8/site-packages/torch/autograd/grad_mode.py", line 27, in decorate_context
    return func(*args, **kwargs)
  File "04_generate_figures.py", line 151, in generate_figs
    img = self.model.compose_templates(
  File "/home/user/villar/PCDNet/src/models/PrototypicalDissentangler.py", line 207, in compose_templates
    cur_mask = masks[:, -1-i]
IndexError: index -2 is out of bounds for dimension 1 with size 1




2021-10-09-14:42:17    NEW_EXP: Starting Figure generation procedure
2021-10-09-14:42:17    INFO: Calling: __init__...
2021-10-09-14:42:17    INFO: Calling: create_directory...
2021-10-09-14:42:17    INFO: Calling: load_data...
2021-10-09-14:42:17    INFO: Calling: setup_model...
2021-10-09-14:42:17    INFO: Calling: setup_model...
2021-10-09-14:42:17    INFO: Calling: load_checkpoint...
2021-10-09-14:42:18    INFO: Calling: generate_figs...
2021-10-09-14:42:19    INFO: Calling: create_directory...
2021-10-09-14:42:19    ERROR: Traceback (most recent call last):
  File "/home/user/villar/PCDNet/src/lib/logger.py", line 24, in try_call_log
    return func(*args, **kwargs)
  File "/home/user/villar/anaconda3/lib/python3.8/site-packages/torch/autograd/grad_mode.py", line 27, in decorate_context
    return func(*args, **kwargs)
  File "04_generate_figures.py", line 153, in generate_figs
    img = self.model.compose_templates(
  File "/home/user/villar/PCDNet/src/models/PrototypicalDissentangler.py", line 207, in compose_templates
    cur_mask = masks[:, -1-i]
IndexError: index -2 is out of bounds for dimension 1 with size 1




2021-10-09-14:42:40    NEW_EXP: Starting Figure generation procedure
2021-10-09-14:42:40    INFO: Calling: __init__...
2021-10-09-14:42:40    INFO: Calling: create_directory...
2021-10-09-14:42:40    INFO: Calling: load_data...
2021-10-09-14:42:40    INFO: Calling: setup_model...
2021-10-09-14:42:40    INFO: Calling: setup_model...
2021-10-09-14:42:40    INFO: Calling: load_checkpoint...
2021-10-09-14:42:42    INFO: Calling: generate_figs...
2021-10-09-14:42:42    INFO: Calling: create_directory...
2021-10-09-14:42:42    INFO: Calling: generate_figs...
2021-10-09-14:42:42    INFO: Calling: create_directory...
2021-10-09-14:42:43    INFO: Calling: generate_figs...
2021-10-09-14:42:43    INFO: Calling: create_directory...
2021-10-09-14:42:43    INFO: Calling: generate_figs...
2021-10-09-14:42:43    INFO: Calling: create_directory...
2021-10-09-14:42:43    INFO: Calling: generate_figs...
2021-10-09-14:42:43    INFO: Calling: create_directory...



2021-10-09-14:54:37    NEW_EXP: Starting Figure generation procedure
2021-10-09-14:54:37    INFO: Calling: __init__...
2021-10-09-14:54:37    INFO: Calling: create_directory...
2021-10-09-14:54:37    INFO: Calling: load_data...
2021-10-09-14:54:37    INFO: Calling: setup_model...
2021-10-09-14:54:37    INFO: Calling: setup_model...
2021-10-09-14:54:37    INFO: Calling: load_checkpoint...
2021-10-09-14:54:39    INFO: Calling: generate_figs...
2021-10-09-14:54:39    ERROR: Traceback (most recent call last):
  File "/home/user/villar/PCDNet/src/lib/logger.py", line 24, in try_call_log
    return func(*args, **kwargs)
  File "/home/user/villar/anaconda3/lib/python3.8/site-packages/torch/autograd/grad_mode.py", line 27, in decorate_context
    return func(*args, **kwargs)
  File "04_generate_figures.py", line 88, in generate_figs
    n_rows = torch.ceil(num_objs // n_cols)
TypeError: ceil(): argument 'input' (position 1) must be Tensor, not int




2021-10-09-14:55:02    NEW_EXP: Starting Figure generation procedure
2021-10-09-14:55:02    INFO: Calling: __init__...
2021-10-09-14:55:02    INFO: Calling: create_directory...
2021-10-09-14:55:02    INFO: Calling: load_data...
2021-10-09-14:55:02    INFO: Calling: setup_model...
2021-10-09-14:55:02    INFO: Calling: setup_model...
2021-10-09-14:55:02    INFO: Calling: load_checkpoint...
2021-10-09-14:55:03    INFO: Calling: generate_figs...
2021-10-09-14:55:04    INFO: Calling: create_directory...
2021-10-09-14:55:04    ERROR: Traceback (most recent call last):
  File "/home/user/villar/PCDNet/src/lib/logger.py", line 24, in try_call_log
    return func(*args, **kwargs)
  File "/home/user/villar/anaconda3/lib/python3.8/site-packages/torch/autograd/grad_mode.py", line 27, in decorate_context
    return func(*args, **kwargs)
  File "04_generate_figures.py", line 115, in generate_figs
    fig, ax = plt.subplots(n_rows, n_cols)
  File "/home/user/villar/anaconda3/lib/python3.8/site-packages/matplotlib/cbook/deprecation.py", line 451, in wrapper
    return func(*args, **kwargs)
  File "/home/user/villar/anaconda3/lib/python3.8/site-packages/matplotlib/pyplot.py", line 1288, in subplots
    axs = fig.subplots(nrows=nrows, ncols=ncols, sharex=sharex, sharey=sharey,
  File "/home/user/villar/anaconda3/lib/python3.8/site-packages/matplotlib/cbook/deprecation.py", line 451, in wrapper
    return func(*args, **kwargs)
  File "/home/user/villar/anaconda3/lib/python3.8/site-packages/matplotlib/figure.py", line 1522, in subplots
    return (self.add_gridspec(nrows, ncols, figure=self, **gridspec_kw)
  File "/home/user/villar/anaconda3/lib/python3.8/site-packages/matplotlib/figure.py", line 2804, in add_gridspec
    gs = GridSpec(nrows=nrows, ncols=ncols, figure=self, **kwargs)
  File "/home/user/villar/anaconda3/lib/python3.8/site-packages/matplotlib/gridspec.py", line 420, in __init__
    GridSpecBase.__init__(self, nrows, ncols,
  File "/home/user/villar/anaconda3/lib/python3.8/site-packages/matplotlib/gridspec.py", line 48, in __init__
    raise ValueError(
ValueError: Number of rows must be a positive integer, not 0




2021-10-09-14:55:20    NEW_EXP: Starting Figure generation procedure
2021-10-09-14:55:20    INFO: Calling: __init__...
2021-10-09-14:55:20    INFO: Calling: create_directory...
2021-10-09-14:55:20    INFO: Calling: load_data...
2021-10-09-14:55:20    INFO: Calling: setup_model...
2021-10-09-14:55:20    INFO: Calling: setup_model...
2021-10-09-14:55:20    INFO: Calling: load_checkpoint...
2021-10-09-14:55:22    INFO: Calling: generate_figs...
2021-10-09-14:55:22    INFO: Calling: create_directory...
2021-10-09-14:55:22    ERROR: Traceback (most recent call last):
  File "/home/user/villar/PCDNet/src/lib/logger.py", line 24, in try_call_log
    return func(*args, **kwargs)
  File "/home/user/villar/anaconda3/lib/python3.8/site-packages/torch/autograd/grad_mode.py", line 27, in decorate_context
    return func(*args, **kwargs)
  File "04_generate_figures.py", line 115, in generate_figs
    fig, ax = plt.subplots(n_rows, n_cols)
  File "/home/user/villar/anaconda3/lib/python3.8/site-packages/matplotlib/cbook/deprecation.py", line 451, in wrapper
    return func(*args, **kwargs)
  File "/home/user/villar/anaconda3/lib/python3.8/site-packages/matplotlib/pyplot.py", line 1288, in subplots
    axs = fig.subplots(nrows=nrows, ncols=ncols, sharex=sharex, sharey=sharey,
  File "/home/user/villar/anaconda3/lib/python3.8/site-packages/matplotlib/cbook/deprecation.py", line 451, in wrapper
    return func(*args, **kwargs)
  File "/home/user/villar/anaconda3/lib/python3.8/site-packages/matplotlib/figure.py", line 1522, in subplots
    return (self.add_gridspec(nrows, ncols, figure=self, **gridspec_kw)
  File "/home/user/villar/anaconda3/lib/python3.8/site-packages/matplotlib/figure.py", line 2804, in add_gridspec
    gs = GridSpec(nrows=nrows, ncols=ncols, figure=self, **kwargs)
  File "/home/user/villar/anaconda3/lib/python3.8/site-packages/matplotlib/gridspec.py", line 420, in __init__
    GridSpecBase.__init__(self, nrows, ncols,
  File "/home/user/villar/anaconda3/lib/python3.8/site-packages/matplotlib/gridspec.py", line 48, in __init__
    raise ValueError(
ValueError: Number of rows must be a positive integer, not 0




2021-10-09-14:56:03    NEW_EXP: Starting Figure generation procedure
2021-10-09-14:56:03    INFO: Calling: __init__...
2021-10-09-14:56:03    INFO: Calling: create_directory...
2021-10-09-14:56:03    INFO: Calling: load_data...
2021-10-09-14:56:03    INFO: Calling: setup_model...
2021-10-09-14:56:03    INFO: Calling: setup_model...
2021-10-09-14:56:03    INFO: Calling: load_checkpoint...
2021-10-09-14:56:04    INFO: Calling: generate_figs...
2021-10-09-14:56:05    INFO: Calling: create_directory...
2021-10-09-14:56:05    ERROR: Traceback (most recent call last):
  File "/home/user/villar/PCDNet/src/lib/logger.py", line 24, in try_call_log
    return func(*args, **kwargs)
  File "/home/user/villar/anaconda3/lib/python3.8/site-packages/torch/autograd/grad_mode.py", line 27, in decorate_context
    return func(*args, **kwargs)
  File "04_generate_figures.py", line 123, in generate_figs
    plt.tight_layout()
  File "/home/user/villar/anaconda3/lib/python3.8/site-packages/matplotlib/cbook/deprecation.py", line 451, in wrapper
    return func(*args, **kwargs)
  File "/home/user/villar/anaconda3/lib/python3.8/site-packages/matplotlib/pyplot.py", line 1506, in tight_layout
    gcf().tight_layout(pad=pad, h_pad=h_pad, w_pad=w_pad, rect=rect)
  File "/home/user/villar/anaconda3/lib/python3.8/site-packages/matplotlib/cbook/deprecation.py", line 411, in wrapper
    return func(*inner_args, **inner_kwargs)
  File "/home/user/villar/anaconda3/lib/python3.8/site-packages/matplotlib/figure.py", line 2613, in tight_layout
    kwargs = get_tight_layout_figure(
  File "/home/user/villar/anaconda3/lib/python3.8/site-packages/matplotlib/tight_layout.py", line 303, in get_tight_layout_figure
    kwargs = auto_adjust_subplotpars(fig, renderer,
  File "/home/user/villar/anaconda3/lib/python3.8/site-packages/matplotlib/tight_layout.py", line 90, in auto_adjust_subplotpars
    fig.transFigure.inverted())
  File "/home/user/villar/anaconda3/lib/python3.8/site-packages/matplotlib/transforms.py", line 1822, in inverted
    self._inverted = Affine2D(inv(mtx), shorthand_name=shorthand_name)
  File "<__array_function__ internals>", line 5, in inv
  File "/home/user/villar/anaconda3/lib/python3.8/site-packages/numpy/linalg/linalg.py", line 546, in inv
    ainv = _umath_linalg.inv(a, signature=signature, extobj=extobj)
  File "/home/user/villar/anaconda3/lib/python3.8/site-packages/numpy/linalg/linalg.py", line 88, in _raise_linalgerror_singular
    raise LinAlgError("Singular matrix")
numpy.linalg.LinAlgError: Singular matrix




2021-10-09-14:56:42    NEW_EXP: Starting Figure generation procedure
2021-10-09-14:56:42    INFO: Calling: __init__...
2021-10-09-14:56:42    INFO: Calling: create_directory...
2021-10-09-14:56:42    INFO: Calling: load_data...
2021-10-09-14:56:42    INFO: Calling: setup_model...
2021-10-09-14:56:42    INFO: Calling: setup_model...
2021-10-09-14:56:42    INFO: Calling: load_checkpoint...
2021-10-09-14:56:43    INFO: Calling: generate_figs...
2021-10-09-14:56:44    INFO: Calling: create_directory...
2021-10-09-14:56:44    INFO: Calling: generate_figs...
2021-10-09-14:56:45    INFO: Calling: create_directory...
2021-10-09-14:56:45    INFO: Calling: generate_figs...
2021-10-09-14:56:45    INFO: Calling: create_directory...
2021-10-09-14:56:46    INFO: Calling: generate_figs...
2021-10-09-14:56:46    INFO: Calling: create_directory...
2021-10-09-14:56:46    INFO: Calling: generate_figs...
2021-10-09-14:56:46    INFO: Calling: create_directory...



2021-10-09-14:58:59    NEW_EXP: Starting Figure generation procedure
2021-10-09-14:58:59    INFO: Calling: __init__...
2021-10-09-14:58:59    INFO: Calling: create_directory...
2021-10-09-14:58:59    INFO: Calling: load_data...
2021-10-09-14:58:59    INFO: Calling: setup_model...
2021-10-09-14:58:59    INFO: Calling: setup_model...
2021-10-09-14:58:59    INFO: Calling: load_checkpoint...
2021-10-09-14:59:01    INFO: Calling: generate_figs...
2021-10-09-14:59:01    INFO: Calling: create_directory...
2021-10-09-14:59:02    INFO: Calling: generate_figs...
2021-10-09-14:59:02    INFO: Calling: create_directory...
2021-10-09-14:59:03    INFO: Calling: generate_figs...
2021-10-09-14:59:03    INFO: Calling: create_directory...
2021-10-09-14:59:03    INFO: Calling: generate_figs...
2021-10-09-14:59:03    INFO: Calling: create_directory...
2021-10-09-14:59:04    INFO: Calling: generate_figs...
2021-10-09-14:59:04    INFO: Calling: create_directory...



2021-10-09-14:59:15    NEW_EXP: Starting Figure generation procedure
2021-10-09-14:59:15    INFO: Calling: __init__...
2021-10-09-14:59:15    INFO: Calling: create_directory...
2021-10-09-14:59:15    INFO: Calling: load_data...
2021-10-09-14:59:15    INFO: Calling: setup_model...
2021-10-09-14:59:15    INFO: Calling: setup_model...
2021-10-09-14:59:15    INFO: Calling: load_checkpoint...
2021-10-09-14:59:17    INFO: Calling: generate_figs...
2021-10-09-14:59:18    INFO: Calling: create_directory...
2021-10-09-14:59:18    INFO: Calling: generate_figs...
2021-10-09-14:59:18    INFO: Calling: create_directory...
2021-10-09-14:59:19    INFO: Calling: generate_figs...
2021-10-09-14:59:19    INFO: Calling: create_directory...
2021-10-09-14:59:20    INFO: Calling: generate_figs...
2021-10-09-14:59:20    INFO: Calling: create_directory...
2021-10-09-14:59:20    INFO: Calling: generate_figs...
2021-10-09-14:59:20    INFO: Calling: create_directory...



2021-10-09-14:59:47    NEW_EXP: Starting Figure generation procedure
2021-10-09-14:59:47    INFO: Calling: __init__...
2021-10-09-14:59:47    INFO: Calling: create_directory...
2021-10-09-14:59:47    INFO: Calling: load_data...
2021-10-09-14:59:47    INFO: Calling: setup_model...
2021-10-09-14:59:47    INFO: Calling: setup_model...
2021-10-09-14:59:47    INFO: Calling: load_checkpoint...
2021-10-09-14:59:48    INFO: Calling: generate_figs...
2021-10-09-14:59:49    INFO: Calling: create_directory...
2021-10-09-14:59:49    INFO: Calling: generate_figs...
2021-10-09-14:59:49    INFO: Calling: create_directory...
2021-10-09-14:59:50    INFO: Calling: generate_figs...
2021-10-09-14:59:50    INFO: Calling: create_directory...
2021-10-09-14:59:51    INFO: Calling: generate_figs...
2021-10-09-14:59:51    INFO: Calling: create_directory...
2021-10-09-14:59:51    INFO: Calling: generate_figs...
2021-10-09-14:59:51    INFO: Calling: create_directory...



2021-10-09-15:00:04    NEW_EXP: Starting Figure generation procedure
2021-10-09-15:00:04    INFO: Calling: __init__...
2021-10-09-15:00:04    INFO: Calling: create_directory...
2021-10-09-15:00:04    INFO: Calling: load_data...
2021-10-09-15:00:04    INFO: Calling: setup_model...
2021-10-09-15:00:04    INFO: Calling: setup_model...
2021-10-09-15:00:04    INFO: Calling: load_checkpoint...
2021-10-09-15:00:06    INFO: Calling: generate_figs...
2021-10-09-15:00:06    INFO: Calling: create_directory...
2021-10-09-15:00:07    INFO: Calling: generate_figs...
2021-10-09-15:00:07    INFO: Calling: create_directory...
2021-10-09-15:00:08    INFO: Calling: generate_figs...
2021-10-09-15:00:08    INFO: Calling: create_directory...
2021-10-09-15:00:08    INFO: Calling: generate_figs...
2021-10-09-15:00:08    INFO: Calling: create_directory...
2021-10-09-15:00:09    INFO: Calling: generate_figs...
2021-10-09-15:00:09    INFO: Calling: create_directory...



2021-10-09-15:00:43    NEW_EXP: Starting Figure generation procedure
2021-10-09-15:00:43    INFO: Calling: __init__...
2021-10-09-15:00:43    INFO: Calling: create_directory...
2021-10-09-15:00:43    INFO: Calling: load_data...
2021-10-09-15:00:43    INFO: Calling: setup_model...
2021-10-09-15:00:43    INFO: Calling: setup_model...
2021-10-09-15:00:43    INFO: Calling: load_checkpoint...
2021-10-09-15:00:44    INFO: Calling: generate_figs...
2021-10-09-15:00:45    INFO: Calling: create_directory...
2021-10-09-15:00:45    ERROR: Traceback (most recent call last):
  File "/home/user/villar/PCDNet/src/lib/logger.py", line 24, in try_call_log
    return func(*args, **kwargs)
  File "/home/user/villar/anaconda3/lib/python3.8/site-packages/torch/autograd/grad_mode.py", line 27, in decorate_context
    return func(*args, **kwargs)
  File "04_generate_figures.py", line 120, in generate_figs
    a.imshow(objects[0, i].cpu().permute(1, 2, 0), vmin=0, vmax=1)
AttributeError: 'numpy.ndarray' object has no attribute 'imshow'




2021-10-09-15:01:49    NEW_EXP: Starting Figure generation procedure
2021-10-09-15:01:49    INFO: Calling: __init__...
2021-10-09-15:01:49    INFO: Calling: create_directory...
2021-10-09-15:01:49    INFO: Calling: load_data...
2021-10-09-15:01:49    INFO: Calling: setup_model...
2021-10-09-15:01:49    INFO: Calling: setup_model...
2021-10-09-15:01:49    INFO: Calling: load_checkpoint...
2021-10-09-15:01:50    INFO: Calling: generate_figs...
2021-10-09-15:01:51    INFO: Calling: create_directory...
2021-10-09-15:01:51    INFO: Calling: generate_figs...
2021-10-09-15:01:51    INFO: Calling: create_directory...
2021-10-09-15:01:51    INFO: Calling: generate_figs...
2021-10-09-15:01:51    INFO: Calling: create_directory...
2021-10-09-15:01:52    INFO: Calling: generate_figs...
2021-10-09-15:01:52    INFO: Calling: create_directory...
2021-10-09-15:01:52    INFO: Calling: generate_figs...
2021-10-09-15:01:52    INFO: Calling: create_directory...



2021-10-09-18:57:08    NEW_EXP: Starting Figure generation procedure
2021-10-09-18:57:08    INFO: Calling: __init__...
2021-10-09-18:57:08    INFO: Calling: create_directory...
2021-10-09-18:57:08    INFO: Calling: load_data...
2021-10-09-18:57:08    INFO: Calling: setup_model...
2021-10-09-18:57:08    INFO: Calling: setup_model...
2021-10-09-18:57:08    INFO: Calling: load_checkpoint...



2021-10-09-18:57:18    NEW_EXP: Starting Figure generation procedure
2021-10-09-18:57:18    INFO: Calling: __init__...
2021-10-09-18:57:18    INFO: Calling: create_directory...
2021-10-09-18:57:18    INFO: Calling: load_data...
2021-10-09-18:57:18    INFO: Calling: setup_model...
2021-10-09-18:57:18    INFO: Calling: setup_model...
2021-10-09-18:57:18    INFO: Calling: load_checkpoint...



2021-10-09-18:57:28    NEW_EXP: Starting Figure generation procedure
2021-10-09-18:57:28    INFO: Calling: __init__...
2021-10-09-18:57:28    INFO: Calling: create_directory...
2021-10-09-18:57:28    INFO: Calling: load_data...
2021-10-09-18:57:28    INFO: Calling: setup_model...
2021-10-09-18:57:28    INFO: Calling: setup_model...
2021-10-09-18:57:28    INFO: Calling: load_checkpoint...



2021-10-09-18:58:01    NEW_EXP: Starting Figure generation procedure
2021-10-09-18:58:01    INFO: Calling: __init__...
2021-10-09-18:58:01    INFO: Calling: create_directory...
2021-10-09-18:58:01    INFO: Calling: load_data...
2021-10-09-18:58:01    INFO: Calling: setup_model...
2021-10-09-18:58:01    INFO: Calling: setup_model...
2021-10-09-18:58:01    INFO: Calling: load_checkpoint...



2021-10-09-18:58:48    NEW_EXP: Starting Figure generation procedure
2021-10-09-18:58:48    INFO: Calling: __init__...
2021-10-09-18:58:48    INFO: Calling: create_directory...
2021-10-09-18:58:48    INFO: Calling: load_data...
2021-10-09-18:58:48    INFO: Calling: setup_model...
2021-10-09-18:58:48    INFO: Calling: setup_model...
2021-10-09-18:58:48    INFO: Calling: load_checkpoint...
2021-10-09-18:58:50    INFO: Calling: generate_figs...
2021-10-09-18:58:50    INFO: Calling: create_directory...
2021-10-09-18:58:51    INFO: Calling: generate_figs...
2021-10-09-18:58:51    INFO: Calling: create_directory...
2021-10-09-18:58:51    INFO: Calling: generate_figs...
2021-10-09-18:58:51    INFO: Calling: create_directory...
2021-10-09-18:58:51    INFO: Calling: generate_figs...
2021-10-09-18:58:51    INFO: Calling: create_directory...
2021-10-09-18:58:51    INFO: Calling: generate_figs...
2021-10-09-18:58:51    INFO: Calling: create_directory...



2021-10-09-18:59:36    NEW_EXP: Starting Figure generation procedure
2021-10-09-18:59:36    INFO: Calling: __init__...
2021-10-09-18:59:36    INFO: Calling: create_directory...
2021-10-09-18:59:36    INFO: Calling: load_data...
2021-10-09-18:59:36    INFO: Calling: setup_model...
2021-10-09-18:59:36    INFO: Calling: setup_model...
2021-10-09-18:59:36    INFO: Calling: load_checkpoint...
2021-10-09-18:59:37    INFO: Calling: generate_figs...
2021-10-09-18:59:38    INFO: Calling: create_directory...
2021-10-09-18:59:38    INFO: Calling: generate_figs...
2021-10-09-18:59:38    INFO: Calling: create_directory...
2021-10-09-18:59:38    INFO: Calling: generate_figs...
2021-10-09-18:59:38    INFO: Calling: create_directory...
2021-10-09-18:59:39    INFO: Calling: generate_figs...
2021-10-09-18:59:39    INFO: Calling: create_directory...
2021-10-09-18:59:39    INFO: Calling: generate_figs...
2021-10-09-18:59:39    INFO: Calling: create_directory...



2021-10-09-19:11:02    NEW_EXP: Starting Figure generation procedure
2021-10-09-19:11:02    INFO: Calling: __init__...
2021-10-09-19:11:02    INFO: Calling: create_directory...
2021-10-09-19:11:02    INFO: Calling: load_data...
2021-10-09-19:11:02    INFO: Calling: setup_model...
2021-10-09-19:11:02    INFO: Calling: setup_model...
2021-10-09-19:11:02    INFO: Calling: load_checkpoint...
2021-10-09-19:11:04    INFO: Calling: generate_figs...
2021-10-09-19:11:05    INFO: Calling: create_directory...
2021-10-09-19:11:05    INFO: Calling: generate_figs...
2021-10-09-19:11:05    INFO: Calling: create_directory...
2021-10-09-19:11:05    INFO: Calling: generate_figs...
2021-10-09-19:11:05    INFO: Calling: create_directory...
2021-10-09-19:11:05    INFO: Calling: generate_figs...
2021-10-09-19:11:05    INFO: Calling: create_directory...
2021-10-09-19:11:06    INFO: Calling: generate_figs...
2021-10-09-19:11:06    INFO: Calling: create_directory...
2021-10-09-19:11:06    INFO: Calling: generate_global_figs...
2021-10-09-19:11:06    ERROR: Traceback (most recent call last):
  File "/home/user/villar/PCDNet/src/lib/logger.py", line 24, in try_call_log
    return func(*args, **kwargs)
  File "/home/user/villar/anaconda3/lib/python3.8/site-packages/torch/autograd/grad_mode.py", line 27, in decorate_context
    return func(*args, **kwargs)
  File "04_generate_figures.py", line 198, in generate_global_figs
    reconstruction, (objects, object_ids, protos) = self.model(imgs)
  File "/home/user/villar/anaconda3/lib/python3.8/site-packages/torch/nn/modules/module.py", line 889, in _call_impl
    result = self.forward(*input, **kwargs)
  File "/home/user/villar/PCDNet/src/models/PrototypicalDissentangler.py", line 254, in forward
    B, C, H, W = x.shape
ValueError: not enough values to unpack (expected 4, got 3)




2021-10-09-19:11:31    NEW_EXP: Starting Figure generation procedure
2021-10-09-19:11:31    INFO: Calling: __init__...
2021-10-09-19:11:31    INFO: Calling: create_directory...
2021-10-09-19:11:31    INFO: Calling: load_data...
2021-10-09-19:11:31    INFO: Calling: setup_model...
2021-10-09-19:11:31    INFO: Calling: setup_model...
2021-10-09-19:11:31    INFO: Calling: load_checkpoint...
2021-10-09-19:11:32    INFO: Calling: generate_figs...
2021-10-09-19:11:33    INFO: Calling: create_directory...
2021-10-09-19:11:33    INFO: Calling: generate_figs...
2021-10-09-19:11:33    INFO: Calling: create_directory...
2021-10-09-19:11:33    INFO: Calling: generate_figs...
2021-10-09-19:11:33    INFO: Calling: create_directory...
2021-10-09-19:11:33    INFO: Calling: generate_figs...
2021-10-09-19:11:34    INFO: Calling: create_directory...
2021-10-09-19:11:34    INFO: Calling: generate_figs...
2021-10-09-19:11:34    INFO: Calling: create_directory...
2021-10-09-19:11:34    INFO: Calling: generate_global_figs...
2021-10-09-19:11:34    ERROR: Traceback (most recent call last):
  File "/home/user/villar/PCDNet/src/lib/logger.py", line 24, in try_call_log
    return func(*args, **kwargs)
  File "/home/user/villar/anaconda3/lib/python3.8/site-packages/torch/autograd/grad_mode.py", line 27, in decorate_context
    return func(*args, **kwargs)
  File "04_generate_figures.py", line 198, in generate_global_figs
    reconstruction, (objects, object_ids, protos) = self.model(imgs)
  File "/home/user/villar/anaconda3/lib/python3.8/site-packages/torch/nn/modules/module.py", line 889, in _call_impl
    result = self.forward(*input, **kwargs)
  File "/home/user/villar/PCDNet/src/models/PrototypicalDissentangler.py", line 286, in forward
    templates, peaks = self.pc_cell(x, protos)
  File "/home/user/villar/anaconda3/lib/python3.8/site-packages/torch/nn/modules/module.py", line 889, in _call_impl
    result = self.forward(*input, **kwargs)
  File "/home/user/villar/PCDNet/src/models/PhaseCorrelationCell.py", line 69, in forward
    f_corr = self.estimate_correlation(signal=x_pad, pattern=t_pad)
  File "/home/user/villar/PCDNet/src/models/PhaseCorrelationCell.py", line 169, in estimate_correlation
    F_corr = freq_ops.complex_prod(Signal, Pattern.conj()) / \
  File "/home/user/villar/PCDNet/src/lib/freq_ops.py", line 35, in complex_prod
    prod_re = x_re * y_re - x_im * y_im
RuntimeError: Expected all tensors to be on the same device, but found at least two devices, cuda:0 and cpu!




2021-10-09-19:12:11    NEW_EXP: Starting Figure generation procedure
2021-10-09-19:12:11    INFO: Calling: __init__...
2021-10-09-19:12:11    INFO: Calling: create_directory...
2021-10-09-19:12:11    INFO: Calling: load_data...
2021-10-09-19:12:11    INFO: Calling: setup_model...
2021-10-09-19:12:11    INFO: Calling: setup_model...
2021-10-09-19:12:11    INFO: Calling: load_checkpoint...
2021-10-09-19:12:13    INFO: Calling: generate_figs...
2021-10-09-19:12:13    INFO: Calling: create_directory...
2021-10-09-19:12:13    INFO: Calling: generate_figs...
2021-10-09-19:12:13    INFO: Calling: create_directory...
2021-10-09-19:12:14    INFO: Calling: generate_figs...
2021-10-09-19:12:14    INFO: Calling: create_directory...
2021-10-09-19:12:14    INFO: Calling: generate_figs...
2021-10-09-19:12:14    INFO: Calling: create_directory...
2021-10-09-19:12:14    INFO: Calling: generate_figs...
2021-10-09-19:12:14    INFO: Calling: create_directory...
2021-10-09-19:12:15    INFO: Calling: generate_global_figs...
2021-10-09-19:12:15    ERROR: Traceback (most recent call last):
  File "/home/user/villar/PCDNet/src/lib/logger.py", line 24, in try_call_log
    return func(*args, **kwargs)
  File "/home/user/villar/anaconda3/lib/python3.8/site-packages/torch/autograd/grad_mode.py", line 27, in decorate_context
    return func(*args, **kwargs)
  File "04_generate_figures.py", line 214, in generate_global_figs
    a = ax[row, col] if n_rows > 1 else ax[col]
IndexError: index 2 is out of bounds for axis 0 with size 2




2021-10-09-19:13:17    NEW_EXP: Starting Figure generation procedure
2021-10-09-19:13:17    INFO: Calling: __init__...
2021-10-09-19:13:17    INFO: Calling: create_directory...
2021-10-09-19:13:17    INFO: Calling: load_data...
2021-10-09-19:13:17    INFO: Calling: setup_model...
2021-10-09-19:13:17    INFO: Calling: setup_model...
2021-10-09-19:13:17    INFO: Calling: load_checkpoint...
2021-10-09-19:13:18    INFO: Calling: generate_figs...
2021-10-09-19:13:19    INFO: Calling: create_directory...
2021-10-09-19:13:19    INFO: Calling: generate_figs...
2021-10-09-19:13:19    INFO: Calling: create_directory...
2021-10-09-19:13:19    INFO: Calling: generate_figs...
2021-10-09-19:13:19    INFO: Calling: create_directory...
2021-10-09-19:13:19    INFO: Calling: generate_figs...
2021-10-09-19:13:19    INFO: Calling: create_directory...
2021-10-09-19:13:20    INFO: Calling: generate_figs...
2021-10-09-19:13:20    INFO: Calling: create_directory...
2021-10-09-19:13:20    INFO: Calling: generate_global_figs...
2021-10-09-19:13:20    ERROR: Traceback (most recent call last):
  File "/home/user/villar/PCDNet/src/lib/logger.py", line 24, in try_call_log
    return func(*args, **kwargs)
  File "/home/user/villar/anaconda3/lib/python3.8/site-packages/torch/autograd/grad_mode.py", line 27, in decorate_context
    return func(*args, **kwargs)
  File "04_generate_figures.py", line 217, in generate_global_figs
    a = ax[row, col] if n_rows > 1 else ax[col]
IndexError: index 2 is out of bounds for axis 0 with size 2




2021-10-09-19:13:44    NEW_EXP: Starting Figure generation procedure
2021-10-09-19:13:44    INFO: Calling: __init__...
2021-10-09-19:13:44    INFO: Calling: create_directory...
2021-10-09-19:13:44    INFO: Calling: load_data...
2021-10-09-19:13:44    INFO: Calling: setup_model...
2021-10-09-19:13:44    INFO: Calling: setup_model...
2021-10-09-19:13:44    INFO: Calling: load_checkpoint...
2021-10-09-19:13:45    INFO: Calling: generate_figs...
2021-10-09-19:13:46    INFO: Calling: create_directory...
2021-10-09-19:13:46    INFO: Calling: generate_figs...
2021-10-09-19:13:46    INFO: Calling: create_directory...
2021-10-09-19:13:47    INFO: Calling: generate_figs...
2021-10-09-19:13:47    INFO: Calling: create_directory...
2021-10-09-19:13:47    INFO: Calling: generate_figs...
2021-10-09-19:13:47    INFO: Calling: create_directory...
2021-10-09-19:13:47    INFO: Calling: generate_figs...
2021-10-09-19:13:47    INFO: Calling: create_directory...
2021-10-09-19:13:47    INFO: Calling: generate_global_figs...
2021-10-09-19:13:47    ERROR: Traceback (most recent call last):
  File "/home/user/villar/PCDNet/src/lib/logger.py", line 24, in try_call_log
    return func(*args, **kwargs)
  File "/home/user/villar/anaconda3/lib/python3.8/site-packages/torch/autograd/grad_mode.py", line 27, in decorate_context
    return func(*args, **kwargs)
  File "04_generate_figures.py", line 216, in generate_global_figs
    a = ax[row, col] if n_rows > 1 else ax[col]
IndexError: index 2 is out of bounds for axis 0 with size 2




2021-10-09-19:14:12    NEW_EXP: Starting Figure generation procedure
2021-10-09-19:14:12    INFO: Calling: __init__...
2021-10-09-19:14:12    INFO: Calling: create_directory...
2021-10-09-19:14:12    INFO: Calling: load_data...
2021-10-09-19:14:12    INFO: Calling: setup_model...
2021-10-09-19:14:12    INFO: Calling: setup_model...
2021-10-09-19:14:12    INFO: Calling: load_checkpoint...
2021-10-09-19:14:14    INFO: Calling: generate_figs...
2021-10-09-19:14:14    INFO: Calling: create_directory...
2021-10-09-19:14:14    INFO: Calling: generate_figs...
2021-10-09-19:14:14    INFO: Calling: create_directory...
2021-10-09-19:14:15    INFO: Calling: generate_figs...
2021-10-09-19:14:15    INFO: Calling: create_directory...
2021-10-09-19:14:15    INFO: Calling: generate_figs...
2021-10-09-19:14:15    INFO: Calling: create_directory...
2021-10-09-19:14:15    INFO: Calling: generate_figs...
2021-10-09-19:14:15    INFO: Calling: create_directory...
2021-10-09-19:14:16    INFO: Calling: generate_global_figs...
2021-10-09-19:14:16    ERROR: Traceback (most recent call last):
  File "/home/user/villar/PCDNet/src/lib/logger.py", line 24, in try_call_log
    return func(*args, **kwargs)
  File "/home/user/villar/anaconda3/lib/python3.8/site-packages/torch/autograd/grad_mode.py", line 27, in decorate_context
    return func(*args, **kwargs)
  File "04_generate_figures.py", line 216, in generate_global_figs
    a = ax[row, col] if n_rows > 1 else ax[col]
IndexError: index 2 is out of bounds for axis 0 with size 2




2021-10-09-19:14:45    NEW_EXP: Starting Figure generation procedure
2021-10-09-19:14:45    INFO: Calling: __init__...
2021-10-09-19:14:45    INFO: Calling: create_directory...
2021-10-09-19:14:45    INFO: Calling: load_data...
2021-10-09-19:14:45    INFO: Calling: setup_model...
2021-10-09-19:14:45    INFO: Calling: setup_model...
2021-10-09-19:14:45    INFO: Calling: load_checkpoint...
2021-10-09-19:14:46    INFO: Calling: generate_figs...
2021-10-09-19:14:47    INFO: Calling: create_directory...
2021-10-09-19:14:47    INFO: Calling: generate_figs...
2021-10-09-19:14:47    INFO: Calling: create_directory...
2021-10-09-19:14:47    INFO: Calling: generate_figs...
2021-10-09-19:14:47    INFO: Calling: create_directory...
2021-10-09-19:14:47    INFO: Calling: generate_figs...
2021-10-09-19:14:47    INFO: Calling: create_directory...
2021-10-09-19:14:48    INFO: Calling: generate_figs...
2021-10-09-19:14:48    INFO: Calling: create_directory...
2021-10-09-19:14:48    INFO: Calling: generate_global_figs...
2021-10-09-19:14:48    ERROR: Traceback (most recent call last):
  File "/home/user/villar/PCDNet/src/lib/logger.py", line 24, in try_call_log
    return func(*args, **kwargs)
  File "/home/user/villar/anaconda3/lib/python3.8/site-packages/torch/autograd/grad_mode.py", line 27, in decorate_context
    return func(*args, **kwargs)
  File "04_generate_figures.py", line 219, in generate_global_figs
    a = ax[row, col] if n_rows > 1 else ax[col]
IndexError: index 2 is out of bounds for axis 0 with size 2




2021-10-09-19:15:14    NEW_EXP: Starting Figure generation procedure
2021-10-09-19:15:14    INFO: Calling: __init__...
2021-10-09-19:15:15    INFO: Calling: create_directory...
2021-10-09-19:15:15    INFO: Calling: load_data...
2021-10-09-19:15:15    INFO: Calling: setup_model...
2021-10-09-19:15:15    INFO: Calling: setup_model...
2021-10-09-19:15:15    INFO: Calling: load_checkpoint...
2021-10-09-19:15:16    INFO: Calling: generate_figs...
2021-10-09-19:15:17    INFO: Calling: create_directory...
2021-10-09-19:15:17    INFO: Calling: generate_figs...
2021-10-09-19:15:17    INFO: Calling: create_directory...
2021-10-09-19:15:17    INFO: Calling: generate_figs...
2021-10-09-19:15:17    INFO: Calling: create_directory...
2021-10-09-19:15:17    INFO: Calling: generate_figs...
2021-10-09-19:15:17    INFO: Calling: create_directory...
2021-10-09-19:15:18    INFO: Calling: generate_figs...
2021-10-09-19:15:18    INFO: Calling: create_directory...
2021-10-09-19:15:18    INFO: Calling: generate_global_figs...



2021-10-09-19:15:53    NEW_EXP: Starting Figure generation procedure
2021-10-09-19:15:53    INFO: Calling: __init__...
2021-10-09-19:15:53    INFO: Calling: create_directory...
2021-10-09-19:15:53    INFO: Calling: load_data...
2021-10-09-19:15:53    INFO: Calling: setup_model...
2021-10-09-19:15:53    INFO: Calling: setup_model...
2021-10-09-19:15:53    INFO: Calling: load_checkpoint...
2021-10-09-19:15:54    INFO: Calling: generate_figs...
2021-10-09-19:15:55    INFO: Calling: create_directory...
2021-10-09-19:15:55    INFO: Calling: generate_figs...
2021-10-09-19:15:55    INFO: Calling: create_directory...
2021-10-09-19:15:55    INFO: Calling: generate_figs...
2021-10-09-19:15:55    INFO: Calling: create_directory...
2021-10-09-19:15:55    INFO: Calling: generate_figs...
2021-10-09-19:15:55    INFO: Calling: create_directory...
2021-10-09-19:15:56    INFO: Calling: generate_figs...
2021-10-09-19:15:56    INFO: Calling: create_directory...
2021-10-09-19:15:56    INFO: Calling: generate_global_figs...



2021-10-09-19:16:58    NEW_EXP: Starting Figure generation procedure
2021-10-09-19:16:58    INFO: Calling: __init__...
2021-10-09-19:16:58    INFO: Calling: create_directory...
2021-10-09-19:16:58    INFO: Calling: load_data...
2021-10-09-19:16:58    INFO: Calling: setup_model...
2021-10-09-19:16:58    INFO: Calling: setup_model...
2021-10-09-19:16:58    INFO: Calling: load_checkpoint...
2021-10-09-19:16:59    INFO: Calling: generate_figs...
2021-10-09-19:17:00    INFO: Calling: create_directory...
2021-10-09-19:17:00    INFO: Calling: generate_figs...
2021-10-09-19:17:00    INFO: Calling: create_directory...
2021-10-09-19:17:00    INFO: Calling: generate_figs...
2021-10-09-19:17:00    INFO: Calling: create_directory...
2021-10-09-19:17:01    INFO: Calling: generate_figs...
2021-10-09-19:17:01    INFO: Calling: create_directory...
2021-10-09-19:17:01    INFO: Calling: generate_figs...
2021-10-09-19:17:01    INFO: Calling: create_directory...
2021-10-09-19:17:01    INFO: Calling: generate_global_figs...



2021-10-09-19:17:28    NEW_EXP: Starting Figure generation procedure
2021-10-09-19:17:28    INFO: Calling: __init__...
2021-10-09-19:17:28    INFO: Calling: create_directory...
2021-10-09-19:17:28    INFO: Calling: load_data...
2021-10-09-19:17:28    INFO: Calling: setup_model...
2021-10-09-19:17:28    INFO: Calling: setup_model...
2021-10-09-19:17:28    INFO: Calling: load_checkpoint...
2021-10-09-19:17:29    INFO: Calling: generate_figs...
2021-10-09-19:17:30    INFO: Calling: create_directory...
2021-10-09-19:17:30    INFO: Calling: generate_figs...
2021-10-09-19:17:30    INFO: Calling: create_directory...
2021-10-09-19:17:31    INFO: Calling: generate_figs...
2021-10-09-19:17:31    INFO: Calling: create_directory...
2021-10-09-19:17:31    INFO: Calling: generate_figs...
2021-10-09-19:17:31    INFO: Calling: create_directory...
2021-10-09-19:17:31    INFO: Calling: generate_figs...
2021-10-09-19:17:31    INFO: Calling: create_directory...
2021-10-09-19:17:31    INFO: Calling: generate_global_figs...



2021-10-10-15:33:58    NEW_EXP: Starting Figure generation procedure
2021-10-10-15:33:58    INFO: Calling: __init__...
2021-10-10-15:33:58    INFO: Calling: create_directory...
2021-10-10-15:33:58    INFO: Calling: load_data...
2021-10-10-15:33:58    INFO: Calling: setup_model...
2021-10-10-15:33:58    INFO: Calling: setup_model...
2021-10-10-15:33:58    INFO: Calling: load_checkpoint...
2021-10-10-15:34:00    INFO: Calling: generate_figs...
2021-10-10-15:34:01    INFO: Calling: create_directory...
2021-10-10-15:34:01    INFO: Calling: generate_figs...
2021-10-10-15:34:01    INFO: Calling: create_directory...
2021-10-10-15:34:01    INFO: Calling: generate_figs...
2021-10-10-15:34:01    INFO: Calling: create_directory...
2021-10-10-15:34:01    INFO: Calling: generate_figs...
2021-10-10-15:34:01    INFO: Calling: create_directory...
2021-10-10-15:34:02    INFO: Calling: generate_figs...
2021-10-10-15:34:02    INFO: Calling: create_directory...
2021-10-10-15:34:02    INFO: Calling: generate_global_figs...



2021-10-10-15:34:36    NEW_EXP: Starting Figure generation procedure
2021-10-10-15:34:36    INFO: Calling: __init__...
2021-10-10-15:34:36    INFO: Calling: create_directory...
2021-10-10-15:34:36    INFO: Calling: load_data...
2021-10-10-15:34:36    INFO: Calling: setup_model...
2021-10-10-15:34:36    INFO: Calling: setup_model...
2021-10-10-15:34:36    INFO: Calling: load_checkpoint...
2021-10-10-15:34:38    INFO: Calling: generate_figs...
2021-10-10-15:34:38    INFO: Calling: create_directory...
2021-10-10-15:34:38    INFO: Calling: generate_figs...
2021-10-10-15:34:38    INFO: Calling: create_directory...
2021-10-10-15:34:39    INFO: Calling: generate_figs...
2021-10-10-15:34:39    INFO: Calling: create_directory...
2021-10-10-15:34:39    INFO: Calling: generate_figs...
2021-10-10-15:34:39    INFO: Calling: create_directory...
2021-10-10-15:34:39    INFO: Calling: generate_figs...
2021-10-10-15:34:39    INFO: Calling: create_directory...
2021-10-10-15:34:39    INFO: Calling: generate_global_figs...



2021-10-10-15:36:32    NEW_EXP: Starting Figure generation procedure
2021-10-10-15:36:32    INFO: Calling: __init__...
2021-10-10-15:36:32    INFO: Calling: create_directory...
2021-10-10-15:36:32    INFO: Calling: load_data...
2021-10-10-15:36:32    INFO: Calling: setup_model...
2021-10-10-15:36:32    INFO: Calling: setup_model...
2021-10-10-15:36:32    INFO: Calling: load_checkpoint...
2021-10-10-15:36:34    INFO: Calling: generate_figs...
2021-10-10-15:36:34    INFO: Calling: create_directory...
2021-10-10-15:36:34    INFO: Calling: generate_figs...
2021-10-10-15:36:34    INFO: Calling: create_directory...
2021-10-10-15:36:35    INFO: Calling: generate_figs...
2021-10-10-15:36:35    INFO: Calling: create_directory...
2021-10-10-15:36:35    INFO: Calling: generate_figs...
2021-10-10-15:36:35    INFO: Calling: create_directory...
2021-10-10-15:36:35    INFO: Calling: generate_figs...
2021-10-10-15:36:35    INFO: Calling: create_directory...
2021-10-10-15:36:35    INFO: Calling: generate_global_figs...



2021-10-10-16:57:55    NEW_EXP: Starting Figure generation procedure
2021-10-10-16:57:55    INFO: Calling: __init__...
2021-10-10-16:57:55    INFO: Calling: create_directory...
2021-10-10-16:57:55    INFO: Calling: load_data...
2021-10-10-16:57:55    INFO: Calling: setup_model...
2021-10-10-16:57:55    INFO: Calling: setup_model...
2021-10-10-16:57:55    INFO: Calling: load_checkpoint...
2021-10-10-16:57:57    INFO: Calling: generate_figs...
2021-10-10-16:57:57    INFO: Calling: create_directory...
2021-10-10-16:57:58    ERROR: Traceback (most recent call last):
  File "/home/user/villar/PCDNet/src/lib/logger.py", line 24, in try_call_log
    return func(*args, **kwargs)
  File "/home/user/villar/anaconda3/lib/python3.8/site-packages/torch/autograd/grad_mode.py", line 27, in decorate_context
    return func(*args, **kwargs)
  File "04_generate_figures.py", line 169, in generate_figs
    img = self.model.compose_templates(
  File "/home/user/villar/PCDNet/src/models/PrototypicalDissentangler.py", line 208, in compose_templates
    cur_recons = cur_obj * cur_mask + cur_recons * (1 - cur_mask)
RuntimeError: The size of tensor a (9) must match the size of tensor b (3) at non-singleton dimension 1




2021-10-10-17:00:30    NEW_EXP: Starting Figure generation procedure
2021-10-10-17:00:30    INFO: Calling: __init__...
2021-10-10-17:00:30    INFO: Calling: create_directory...
2021-10-10-17:00:30    INFO: Calling: load_data...
2021-10-10-17:00:30    INFO: Calling: setup_model...
2021-10-10-17:00:30    INFO: Calling: setup_model...
2021-10-10-17:00:30    INFO: Calling: load_checkpoint...
2021-10-10-17:00:32    INFO: Calling: generate_figs...
2021-10-10-17:00:33    INFO: Calling: create_directory...
2021-10-10-17:00:33    INFO: Calling: generate_figs...
2021-10-10-17:00:33    INFO: Calling: create_directory...
2021-10-10-17:00:33    INFO: Calling: generate_figs...
2021-10-10-17:00:33    INFO: Calling: create_directory...
2021-10-10-17:00:33    INFO: Calling: generate_figs...
2021-10-10-17:00:33    INFO: Calling: create_directory...
2021-10-10-17:00:34    INFO: Calling: generate_figs...
2021-10-10-17:00:34    INFO: Calling: create_directory...
2021-10-10-17:00:34    INFO: Calling: generate_global_figs...
